Workbook

Sheet Summary
A1: House BUS - Mass & Payload Summary
A3: Metric | B3: Value | C3: Unit | D3: Comment
A4: Curb weight - baseline | B4: ='Mass Budget'!$C$37 -> 18240 | C4: lb | D4: Conventional steel-heavy build
A5: Curb weight - optimized | B5: ='Mass Budget'!$C$38 -> 13270 | C5: lb | D5: Advanced-material target
A6: Reduction vs baseline | B6: ='Mass Budget'!$C$40 -> 0.27247807 | D6: Target 20-25%
A7: Occupants payload | B7: =Assumptions!$B$5*Assumptions!$B$6 -> 350 | C7: lb
A8: Water payload | B8: =Assumptions!$B$7*Assumptions!$B$8 -> 417 | C8: lb
A9: Food & provisions | B9: =Assumptions!$B$9 -> 500 | C9: lb
A10: Personal effects & gear | B10: =Assumptions!$B$10 -> 500 | C10: lb
A11: Total payload | B11: =SUM(B7:B10) -> 1767 | C11: lb
A12: Loaded weight (curb + payload) | B12: ='Mass Budget'!$C$38+B11 -> 15037 | C12: lb
A13: GVWR target | B13: =Assumptions!$B$4 -> 19500 | C13: lb
A14: Margin under GVWR | B14: =B13-B12 -> 4463 | C14: lb | D14: Positive = within rating
A15: Margin % | B15: =B14/B13 -> 0.22887179
A16: Curb CG from front | B16: ='Mass Budget'!$C$41 -> 156.21703 | C16: in | D16: Lower battery centers it
A17: Rear axle load (loaded) | B17: =B12*(B16-Assumptions!$B$11)/(Assumptions!$B$12-Assumptions!$B$11) -> 7963.669 | C17: lb | D17: Approx, using curb CG
A18: Front axle load (loaded) | B18: =B12-B17 -> 7073.331 | C18: lb
A20: Verdict | B20: =IF(B14>=0,"Within GVWR by "&TEXT(B14,"#,##0")&" lb","OVER GVWR by "&TEXT(-B14,"#,##0")&" lb") -> Within GVWR by 4,463 lb
A22: v0.1 estimate. Battery (~3,480 lb) is the fixed anchor; the strip comes from structure, body, interior, and wiring. Update component cells as real parts are chosen.

Sheet Assumptions
A1: Mass Budget - Assumptions (edit blue)
A3: Parameter | B3: Value | C3: Unit | D3: Note
A4: GVWR target | B4: 19500 | C4: lb | D4: Class 5 ~19,500; Class 6 ~26,000 - set your target
A5: Occupants | B5: 2 | C5: persons | D5: Design occupancy
A6: Weight per occupant | B6: 175 | C6: lb
A7: Onboard water | B7: 50 | C7: gal | D7: Drinking + grey, design fill
A8: Water weight | B8: 8.34 | C8: lb/gal | D8: Constant
A9: Food & provisions | B9: 500 | C9: lb | D9: Boondocking stores
A10: Personal effects & gear | B10: 500 | C10: lb
A11: Front axle position | B11: 45 | C11: in | D11: From front bumper, for axle-load split
A12: Rear axle position | B12: 255 | C12: in

Sheet Mass Budget
A1: House BUS - Mass & Payload Budget (v0.1)
A2: Group | B2: Component | C2: Baseline (lb) | D2: Material strategy | E2: Optimized (lb) | F2: Saving (lb) | G2: CG x (in) | H2: Moment (lb-in)
A3: Structure | B3: Chassis frame / spine | C3: 2500 | D3: steel frame -> structural-pack spine + Al/composite stub rails | E3: 1400 | F3: =C3-E3 -> 1100 | G3: 150 | H3: =E3*G3 -> 210000
A4: Structure | B4: Body shell & panels | C4: 2500 | D4: steel -> carbon/glass over foam core | E4: 1200 | F4: =C4-E4 -> 1300 | G4: 150 | H4: =E4*G4 -> 180000
A5: Structure | B5: Roof + reinforcement | C5: 600 | D5: steel -> composite + solar mounts | E5: 350 | F5: =C5-E5 -> 250 | G5: 150 | H5: =E5*G5 -> 52500
A6: Structure | B6: Insulation (high-R) | C6: 350 | D6: batt -> vacuum panel / aerogel | E6: 300 | F6: =C6-E6 -> 50 | G6: 150 | H6: =E6*G6 -> 45000
A7: Structure | B7: Glazing | C7: 350 | D7: glass -> double-layer polycarbonate | E7: 180 | F7: =C7-E7 -> 170 | G7: 150 | H7: =E7*G7 -> 27000
A8: Structure | B8: Interior walls / cabinets | C8: 900 | D8: ply+metal -> EPP foam + CF skins | E8: 350 | F8: =C8-E8 -> 550 | G8: 160 | H8: =E8*G8 -> 56000
A9: Structure | B9: Flooring | C9: 300 | D9: conventional -> composite | E9: 180 | F9: =C9-E9 -> 120 | G9: 150 | H9: =E9*G9 -> 27000
A10: Running gear | B10: E-axle + motor + reduction | C10: 1100 | D10: efficient single e-axle | E10: 950 | F10: =C10-E10 -> 150 | G10: 250 | H10: =E10*G10 -> 237500
A11: Running gear | B11: Air suspension | C11: 600 | D11: lightweight air ride | E11: 500 | F11: =C11-E11 -> 100 | G11: 160 | H11: =E11*G11 -> 80000
A12: Running gear | B12: Wheels & tires | C12: 600 | D12: steel -> alloy, low rolling resistance | E12: 550 | F12: =C12-E12 -> 50 | G12: 150 | H12: =E12*G12 -> 82500
A13: Running gear | B13: Steering & brakes | C13: 350 | E13: 320 | F13: =C13-E13 -> 30 | G13: 110 | H13: =E13*G13 -> 35200
A14: Energy | B14: Battery pack 300 kWh | C14: 4000 | D14: sodium-ion CTP/structural (CATL Naxtra ~175 Wh/kg, mass-prod 2025) | E14: 3780 | F14: =C14-E14 -> 220 | G14: 150 | H14: =E14*G14 -> 567000
A15: Energy | B15: Power electronics | C15: 250 | D15: inverter / DC-DC | E15: 200 | F15: =C15-E15 -> 50 | G15: 240 | H15: =E15*G15 -> 48000
A16: Energy | B16: Wiring & harness | C16: 350 | D16: 12V copper -> 48V/800V thin + TE connectors | E16: 180 | F16: =C16-E16 -> 170 | G16: 150 | H16: =E16*G16 -> 27000
A17: Energy | B17: Solar (roof + deployable) | C17: 350 | D17: glass -> flexible / semi-flex | E17: 300 | F17: =C17-E17 -> 50 | G17: 150 | H17: =E17*G17 -> 45000
A18: Energy | B18: Inverter / charger | C18: 120 | E18: 100 | F18: =C18-E18 -> 20 | G18: 200 | H18: =E18*G18 -> 20000
A19: Thermal | B19: HVAC / heat-pump core | C19: 300 | D19: integrated unit (cool/heat/vent) | E19: 280 | F19: =C19-E19 -> 20 | G19: 100 | H19: =E19*G19 -> 28000
A20: Thermal | B20: Coolant loop, pumps, buffers | C20: 250 | E20: 200 | F20: =C20-E20 -> 50 | G20: 150 | H20: =E20*G20 -> 30000
A21: Thermal | B21: Diesel CHP genset 3.5 kW | C21: 200 | E21: 180 | F21: =C21-E21 -> 20 | G21: 110 | H21: =E21*G21 -> 19800
A22: Thermal | B22: Hot water tank + drying | C22: 150 | E22: 120 | F22: =C22-E22 -> 30 | G22: 120 | H22: =E22*G22 -> 14400
A23: Water | B23: Water tanks (SS drink + grey) | C23: 250 | D23: smaller closed-loop | E23: 200 | F23: =C23-E23 -> 50 | G23: 130 | H23: =E23*G23 -> 26000
A24: Water | B24: Reticulating shower + filters | C24: 90 | E24: 60 | F24: =C24-E24 -> 30 | G24: 200 | H24: =E24*G24 -> 12000
A25: Water | B25: Composting toilet | C25: 60 | E25: 50 | F25: =C25-E25 -> 10 | G25: 210 | H25: =E25*G25 -> 10500
A26: Water | B26: Plumbing & pumps | C26: 120 | E26: 90 | F26: =C26-E26 -> 30 | G26: 160 | H26: =E26*G26 -> 14400
A27: Habitability | B27: Fridge / freezer | C27: 200 | D27: efficient DC | E27: 180 | F27: =C27-E27 -> 20 | G27: 90 | H27: =E27*G27 -> 16200
A28: Habitability | B28: Cooking (induction/microwave) | C28: 100 | E28: 90 | F28: =C28-E28 -> 10 | G28: 90 | H28: =E28*G28 -> 8100
A29: Habitability | B29: Washer / dryer (heat-pump) | C29: 200 | E29: 180 | F29: =C29-E29 -> 20 | G29: 110 | H29: =E29*G29 -> 19800
A30: Habitability | B30: Bed + climate bed | C30: 200 | E30: 150 | F30: =C30-E30 -> 50 | G30: 270 | H30: =E30*G30 -> 40500
A31: Habitability | B31: Furniture & seating | C31: 300 | D31: wood -> foam / composite | E31: 180 | F31: =C31-E31 -> 120 | G31: 120 | H31: =E31*G31 -> 21600
A32: Habitability | B32: Hydroponics system | C32: 120 | E32: 100 | F32: =C32-E32 -> 20 | G32: 200 | H32: =E32*G32 -> 20000
A33: Controls/misc | B33: Computer, controls, sensors | C33: 80 | E33: 70 | F33: =C33-E33 -> 10 | G33: 100 | H33: =E33*G33 -> 7000
A34: Controls/misc | B34: Misc hardware & fasteners | C34: 400 | D34: steel -> Al / composite | E34: 300 | F34: =C34-E34 -> 100 | G34: 150 | H34: =E34*G34 -> 45000
B35: TOTAL | C35: =SUM(C3:C34) -> 18240 | E35: =SUM(E3:E34) -> 13270 | F35: =SUM(F3:F34) -> 4970 | H35: =SUM(H3:H34) -> 2073000
A37: Curb weight - baseline (lb) | C37: =C35 -> 18240
A38: Curb weight - optimized (lb) | C38: =E35 -> 13270
A39: Total mass saved (lb) | C39: =F35 -> 4970
A40: Reduction vs baseline | C40: =F35/C35 -> 0.27247807
A41: Curb CG from front (in) | C41: =H35/E35 -> 156.21703
...
