Workbook

Sheet Summary
A1: House BUS - BOM Cost Summary (approximate, USD)
A3: Group | B3: Low ($) | C3: High ($) | D3: Note
A4: Vehicle base | B4: =SUMIF(BOM!$A:$A,A4,BOM!$F:$F) -> 6000 | C4: =SUMIF(BOM!$A:$A,A4,BOM!$G:$G) -> 25000
A5: Structure & body | B5: =SUMIF(BOM!$A:$A,A5,BOM!$F:$F) -> 16500 | C5: =SUMIF(BOM!$A:$A,A5,BOM!$G:$G) -> 47000
A6: Running gear | B6: =SUMIF(BOM!$A:$A,A6,BOM!$F:$F) -> 23000 | C6: =SUMIF(BOM!$A:$A,A6,BOM!$G:$G) -> 47000
A7: Energy & electrical | B7: =SUMIF(BOM!$A:$A,A7,BOM!$F:$F) -> 34300 | C7: =SUMIF(BOM!$A:$A,A7,BOM!$G:$G) -> 65500
A8: Thermal | B8: =SUMIF(BOM!$A:$A,A8,BOM!$F:$F) -> 10000 | C8: =SUMIF(BOM!$A:$A,A8,BOM!$G:$G) -> 30000
A9: Water & sanitation | B9: =SUMIF(BOM!$A:$A,A9,BOM!$F:$F) -> 5200 | C9: =SUMIF(BOM!$A:$A,A9,BOM!$G:$G) -> 16200
A10: Habitability | B10: =SUMIF(BOM!$A:$A,A10,BOM!$F:$F) -> 10600 | C10: =SUMIF(BOM!$A:$A,A10,BOM!$G:$G) -> 30500
A11: Controls & safety | B11: =SUMIF(BOM!$A:$A,A11,BOM!$F:$F) -> 4900 | C11: =SUMIF(BOM!$A:$A,A11,BOM!$G:$G) -> 14000
A12: Misc | B12: =SUMIF(BOM!$A:$A,A12,BOM!$F:$F) -> 3000 | C12: =SUMIF(BOM!$A:$A,A12,BOM!$G:$G) -> 8000
A13: Subtotal | B13: =SUM(B4:B12) -> 113500 | C13: =SUM(C4:C12) -> 283200
A14: Contingency (25%) | B14: =0.25*B13 -> 28375 | C14: =0.25*C13 -> 70800
A15: BUILD TOTAL | B15: =B13+B14 -> 141875 | C15: =C13+C14 -> 354000
A17: v0.1 order-of-magnitude. Wide bands = lean V1 conversion (low) vs full ground-up with all features (high). Overlaps the roadmap's $90-160k V1 class at the low end; the high end includes sauna, RO, deployable solar, premium finishes, composite ground-up.
A18: Battery = 300 kWh x sodium $/kWh (Energy group). Cross-check component list against the mass budget (same groups).

Sheet BOM
A1: House BUS - Bill of Materials (v0.1, approximate)
A2: Group | B2: Component | C2: Qty | D2: Unit low ($) | E2: Unit high ($) | F2: Ext low ($) | G2: Ext high ($) | H2: Notes / sourcing
A3: Vehicle base | B3: Donor bus (used 25-27ft) OR cab-chassis glider | C3: 1 | D3: 6000 | E3: 25000 | F3: =C3*D3 -> 6000 | G3: =C3*E3 -> 25000 | H3: Conversion (V1) vs ground-up
A4: Structure & body | B4: Composite body panels (carbon/glass over foam) | C4: 1 | D4: 5000 | E4: 15000 | F4: =C4*D4 -> 5000 | G4: =C4*E4 -> 15000
A5: Structure & body | B5: EPP foam interior structure + CF skins | C5: 1 | D5: 2000 | E5: 6000 | F5: =C5*D5 -> 2000 | G5: =C5*E5 -> 6000
A6: Structure & body | B6: High-R insulation (vacuum panel / aerogel) | C6: 1 | D6: 2000 | E6: 6000 | F6: =C6*D6 -> 2000 | G6: =C6*E6 -> 6000 | H6: Premium insulation is pricey
A7: Structure & body | B7: Polycarbonate glazing + insulated covers | C7: 1 | D7: 1500 | E7: 4000 | F7: =C7*D7 -> 1500 | G7: =C7*E7 -> 4000
A8: Structure & body | B8: Structural pack enclosure / fab | C8: 1 | D8: 3000 | E8: 8000 | F8: =C8*D8 -> 3000 | G8: =C8*E8 -> 8000 | H8: 3D-print composite vs cast Al
A9: Structure & body | B9: Slide-out mechanisms | C9: 2 | D9: 1500 | E9: 4000 | F9: =C9*D9 -> 3000 | G9: =C9*E9 -> 8000 | H9: per slide-out
A10: Running gear | B10: E-axle + motor + inverter | C10: 1 | D10: 18000 | E10: 35000 | F10: =C10*D10 -> 18000 | G10: =C10*E10 -> 35000 | H10: ~200-250 kW EV bus drivetrain
A11: Running gear | B11: Adjustable air suspension | C11: 1 | D11: 2500 | E11: 6000 | F11: =C11*D11 -> 2500 | G11: =C11*E11 -> 6000
A12: Running gear | B12: Wheels, tires, brakes, steering | C12: 1 | D12: 2500 | E12: 6000 | F12: =C12*D12 -> 2500 | G12: =C12*E12 -> 6000
A13: Energy & electrical | B13: Sodium-ion cells/modules (per kWh) | C13: 300 | D13: 70 | E13: 110 | F13: =C13*D13 -> 21000 | G13: =C13*E13 -> 33000 | H13: CATL Naxtra-class; sodium cost advantage
A14: Energy & electrical | B14: BMS (HV, cell-level) | C14: 1 | D14: 2000 | E14: 5000 | F14: =C14*D14 -> 2000 | G14: =C14*E14 -> 5000
A15: Energy & electrical | B15: DC-DC 800->48 V (stackable) | C15: 1 | D15: 1500 | E15: 4000 | F15: =C15*D15 -> 1500 | G15: =C15*E15 -> 4000
A16: Energy & electrical | B16: Inverter/charger (Victron-class) | C16: 1 | D16: 1200 | E16: 2500 | F16: =C16*D16 -> 1200 | G16: =C16*E16 -> 2500
A17: Energy & electrical | B17: Solar MPPT controllers | C17: 1 | D17: 600 | E17: 1500 | F17: =C17*D17 -> 600 | G17: =C17*E17 -> 1500
A18: Energy & electrical | B18: Solar array (roof + deployable) | C18: 1 | D18: 3000 | E18: 5500 | F18: =C18*D18 -> 3000 | G18: =C18*E18 -> 5500
A19: Energy & electrical | B19: TE 48V connectors + harness + cable | C19: 1 | D19: 1500 | E19: 4000 | F19: =C19*D19 -> 1500 | G19: =C19*E19 -> 4000
A20: Energy & electrical | B20: PDM / fusing / contactors / busbars | C20: 1 | D20: 1500 | E20: 4000 | F20: =C20*D20 -> 1500 | G20: =C20*E20 -> 4000
A21: Energy & electrical | B21: Charge inlets (MCS + NACS hardware) | C21: 1 | D21: 2000 | E21: 6000 | F21: =C21*D21 -> 2000 | G21: =C21*E21 -> 6000 | H21: Two standards
A22: Thermal | B22: Heat-pump/AC core + dual compressors (EV-grade) | C22: 1 | D22: 3000 | E22: 9000 | F22: =C22*D22 -> 3000 | G22: =C22*E22 -> 9000
A23: Thermal | B23: Multi-port manifold (custom) + valves | C23: 1 | D23: 1500 | E23: 4000 | F23: =C23*D23 -> 1500 | G23: =C23*E23 -> 4000 | H23: beyond-Octovalve
A24: Thermal | B24: Coolant pumps, exchangers, lines, glycol, buffers | C24: 1 | D24: 1500 | E24: 4000 | F24: =C24*D24 -> 1500 | G24: =C24*E24 -> 4000
A25: Thermal | B25: Diesel CHP genset 3.5 kW + heat recovery | C25: 1 | D25: 3000 | E25: 10000 | F25: =C25*D25 -> 3000 | G25: =C25*E25 -> 10000
A26: Thermal | B26: Hot-water tank + drying coil + dehumidifier | C26: 1 | D26: 1000 | E26: 3000 | F26: =C26*D26 -> 1000 | G26: =C26*E26 -> 3000
A27: Water & sanitation | B27: SS drinking tank + external inlet + pump | C27: 1 | D27: 800 | E27: 2500 | F27: =C27*D27 -> 800 | G27: =C27*E27 -> 2500
A28: Water & sanitation | B28: Reticulating shower loop + filters + UV | C28: 1 | D28: 1500 | E28: 4000 | F28: =C28*D28 -> 1500 | G28: =C28*E28 -> 4000
A29: Water & sanitation | B29: Composting toilet + urine diverter | C29: 1 | D29: 800 | E29: 2000 | F29: =C29*D29 -> 800 | G29: =C29*E29 -> 2000
A30: Water & sanitation | B30: Greywater + plumbing + pumps | C30: 1 | D30: 800 | E30: 2500 | F30: =C30*D30 -> 800 | G30: =C30*E30 -> 2500
A31: Water & sanitation | B31: RO/electrodialysis (urine salt-strip) | C31: 1 | D31: 1000 | E31: 4000 | F31: =C31*D31 -> 1000 | G31: =C31*E31 -> 4000 | H31: future/optional
A32: Water & sanitation | B32: Rainwater catchment (optional) | C32: 1 | D32: 300 | E32: 1200 | F32: =C32*D32 -> 300 | G32: =C32*E32 -> 1200
A33: Habitability | B33: Fridge/freezer (cold-store + boxes) | C33: 1 | D33: 600 | E33: 2000 | F33: =C33*D33 -> 600 | G33: =C33*E33 -> 2000 | H33: on the thermal loop
A34: Habitability | B34: Induction + microwave | C34: 1 | D34: 500 | E34: 1500 | F34: =C34*D34 -> 500 | G34: =C34*E34 -> 1500
A35: Habitability | B35: Heat-pump washer/dryer | C35: 1 | D35: 1000 | E35: 2500 | F35: =C35*D35 -> 1000 | G35: =C35*E35 -> 2500
A36: Habitability | B36: Climate bed + mattress | C36: 1 | D36: 1000 | E36: 3000 | F36: =C36*D36 -> 1000 | G36: =C36*E36 -> 3000
A37: Habitability | B37: Hydroponics (RDWC/NFT + LED + dosers) | C37: 1 | D37: 1000 | E37: 2500 | F37: =C37*D37 -> 1000 | G37: =C37*E37 -> 2500
A38: Habitability | B38: Galley / cabinetry / finishes / upholstery | C38: 1 | D38: 5000 | E38: 15000 | F38: =C38*D38 -> 5000 | G38: =C38*E38 -> 15000 | H38: DIY vs pro finish
A39: Habitability | B39: Sauna (compact electric) | C39: 1 | D39: 1500 | E39: 4000 | F39: =C39*D39 -> 1500 | G39: =C39*E39 -> 4000
A40: Controls & safety | B40: Linux host + tablet + edge nodes | C40: 1 | D40: 1500 | E40: 4000 | F40: =C40*D40 -> 1500 | G40: =C40*E40 -> 4000
...
