Workbook

Sheet Summary
A1: House BUS — Energy & Thermal Model (v2)
A2: Shared 300 kWh structural pack · 25–27 ft + slide-outs · 2 occ · 3.5 kW diesel CHP · ski-weekend winter.
A4: Metric | B4: Value | C4: Unit | D4: Comment
A5: Pack
A6: Usable pack energy | B6: ='Pack & Range'!C4 -> 270 | C6: kWh | D6: 90% of 300 kWh
A7: House-available (after reserve) | B7: ='Pack & Range'!C5 -> 190 | C7: kWh | D7: minus 80 kWh drive floor
A8: Driving range (usable) | B8: ='Pack & Range'!C14 -> 245.45455 | C8: miles | D8: at 1.1 kWh/mi
A9: Summer
A10: Daily house demand | B10: ='Summer Day'!C13 -> 15.2582 | C10: kWh/day | D10: base + cooling
A11: Solar generation (parked) | B11: ='Summer Day'!C14 -> 26.076 | C11: kWh/day | D11: 6 kW array
A12: Net vs solar | B12: ='Summer Day'!C15 -> 10.8178 | C12: kWh/day | D12: + = surplus charges pack
A13: Winter ski weekend
A14: Total heat demand | B14: ='Winter Weekend'!C7 -> 32.9536 | C14: kWh/day | D14: cabin + hot water at −10°C
A15: Pack-only autonomy | B15: ='Pack & Range'!C9 -> 12.76032 | C15: days | D15: no genset, with winter solar
A16: Genset runtime (hold pack) | B16: ='Winter Weekend'!C15 -> 2.3205053 | C16: h/day | D16: diesel CHP, net-zero pack
A17: Diesel use (held) | B17: ='Winter Weekend'!C17 -> 2.7072562 | C17: L/day | D17: if staying put indefinitely
A19: Takeaway | B19: ="Pack alone covers ~"&TEXT('Pack & Range'!C9,"0")&" winter days; genset only needed for longer/colder stays." -> Pack alone covers ~13 winter days; genset only needed for longer/colder stays.
A21: Design model, not measured. Slide-out thermal bridging is in the U-value; deep-winter full-time living is out of scope by design.

Sheet Assumptions
A1: House BUS — Design Assumptions (v2, locked decisions)
A2: Edit blue/yellow inputs. Locked: 25–27 ft + slide-outs · 2 occ (4 max) · 800V · ~300 kWh structural pack · 3.5 kW diesel CHP.
A3: Parameter | B3: Value | C3: Unit | D3: Note
A4: General & Occupancy
A5: Occupants (design) | B5: 2 | C5: persons | D5: Full-time design occupancy
A6: Occupants (max squeeze) | B6: 4 | C6: persons | D6: Squeeze capacity (e.g. with kids)
A7: Envelope & Thermal
A8: Envelope area | B8: 58 | C8: m² | D8: 25–27 ft shell incl. modest slide-outs
A9: Overall U-value | B9: 0.7 | C9: W/m²K | D9: Slightly raised to allow slide-out thermal bridging (accepted)
A10: UA (heat-loss coeff.) | B10: =B8*B9 -> 40.6 | C10: W/K | D10: Heat-loss coefficient = area × U
A11: Climate Design Points
A12: Indoor setpoint (winter) | B12: 20 | C12: °C | D12: Winter indoor setpoint
A13: Winter design outdoor | B13: -10 | C13: °C | D13: Ski-weekend design low (not full-time deep winter)
A14: Indoor setpoint (summer) | B14: 24 | C14: °C | D14: Summer indoor setpoint
A15: Summer design outdoor | B15: 33 | C15: °C | D15: Summer design high
A16: Summer solar heat gain | B16: 600 | C16: W | D16: Summer solar heat gain
A17: Summer solar gain hours | B17: 8 | C17: h | D17: Hours of peak solar gain
A18: Heat Pump
A19: COP cooling | B19: 3 | C19: – | D19: COP cooling
A20: COP heating (cold) | B20: 2.2 | C20: – | D20: COP heating at the ski-weekend design low
A21: Domestic Hot Water
A22: Hot water use | B22: 40 | C22: L/p/day | D22: Hot water use
A23: Hot water target temp | B23: 48 | C23: °C | D23: Hot water target
A24: Cold inlet (winter) | B24: 8 | C24: °C | D24: Cold inlet, winter
A25: Cold inlet (summer) | B25: 15 | C25: °C | D25: Cold inlet, summer
A26: Water specific heat | B26: 1.163 | C26: Wh/L/K | D26: Water specific heat (constant)
A27: CHP Diesel Genset (winter)
A28: Genset electrical output | B28: 3.5 | C28: kW | D28: Electrical output (3–4 kW class)
A29: Genset elec. efficiency | B29: 0.3 | C29: frac | D29: Diesel→electricity efficiency
A30: Heat recovery fraction | B30: 0.55 | C30: frac | D30: Fuel→recovered heat (to pack + cabin via Octovalve loop)
A31: Diesel energy content | B31: 10 | C31: kWh/L | D31: Diesel energy content
A32: Solar
A33: Roof array (driving) | B33: 3.5 | C33: kW | D33: Roof array (available while driving)
A34: Parked total array | B34: 6 | C34: kW | D34: Parked total: roof + deployable + side-wall
A35: Peak sun hours (summer) | B35: 5.3 | C35: h/day | D35: Peak sun hours, summer (CT/NYC)
A36: Peak sun hours (winter) | B36: 2.2 | C36: h/day | D36: Peak sun hours, winter
A37: Solar derate | B37: 0.82 | C37: frac | D37: System derate
A38: Shared Structural Battery Pack
A39: Total pack capacity | B39: 300 | C39: kWh | D39: Total pack (sodium structural floor by build time)
A40: Usable SOC window | B40: 0.9 | C40: frac | D40: Usable SOC window (5–95%)
...

Sheet Electrical Loads
A1: Base Electrical Loads (full-amenity, non-HVAC)
A2: Device | B2: Power (W) | C2: Hours/day | D2: Wh/day
A3: LED lighting | B3: 50 | C3: 5 | D3: =B3*C3 -> 250
A4: Fridge (DC compressor) | B4: 50 | C4: 24 | D4: =B4*C4 -> 1200
A5: Freezer (DC compressor) | B5: 45 | C5: 24 | D5: =B5*C5 -> 1080
A6: Induction cooking | B6: 1800 | C6: 0.8 | D6: =B6*C6 -> 1440
A7: Microwave | B7: 1000 | C7: 0.2 | D7: =B7*C7 -> 200
A8: Dishwasher (efficient) | B8: 600 | C8: 0.4 | D8: =B8*C8 -> 240
A9: Heat-pump washer/dryer | B9: 500 | C9: 0.7 | D9: =B9*C9 -> 350
A10: Computer (Linux+Win) | B10: 120 | C10: 10 | D10: =B10*C10 -> 1200
A11: TV / electronics | B11: 80 | C11: 4 | D11: =B11*C11 -> 320
A12: Water pumps | B12: 50 | C12: 1 | D12: =B12*C12 -> 50
A13: Coolant circulation pumps | B13: 40 | C13: 10 | D13: =B13*C13 -> 400
A14: ERV ventilation (heat-recovery) | B14: 35 | C14: 18 | D14: =B14*C14 -> 630
... A18: Standby / misc | B18: 30 | C18: 24 | D18: =B18*C18 -> 720
A19: Total (Wh/day) | D19: =SUM(D3:D18) -> 10735
A21: Base electric demand (kWh/day) | D21: =D19/1000 -> 10.735

Sheet Summer Day
A1: Summer Day — off-grid, solar vs. load
A3: A. Cabin cooling
A4: ΔT (outdoor − indoor) | C4: =Assumptions!$B$15-Assumptions!$B$14 -> 9 | D4: K
A5: Cabin cooling load | C5: =(Assumptions!$B$10*C4*24+Assumptions!$B$16*Assumptions!$B$17)/1000 -> 13.5696 | D5: kWh thermal
A6: Electricity for cooling | C6: =C5/Assumptions!$B$19 -> 4.5232 | D6: kWh elec
A7: B. Hot water from recovered heat
A8: DHW thermal demand | C8: =Assumptions!$B$5*Assumptions!$B$22*Assumptions!$B$26*(Assumptions!$B$23-Assumptions!$B$25)/1000 -> 3.07032 | D8: kWh thermal
A9: Condenser heat available | C9: =C5+C6 -> 18.0928 | D9: kWh thermal
A10: DHW electric top-up | C10: =MAX(0,C8-C9) -> 0 | D10: kWh elec
A11: C. Daily balance
A12: Base electric demand | C12: ='Electrical Loads'!$D$21 -> 10.735 | D12: kWh
A13: Total electric demand | C13: =C12+C6+C10 -> 15.2582 | D13: kWh
A14: Solar generation (parked) | C14: =Assumptions!$B$34*Assumptions!$B$35*Assumptions!$B$37 -> 26.076 | D14: kWh
A15: Net (solar − demand) | C15: =C14-C13 -> 10.8178 | D15: kWh

Sheet Winter Weekend
A1: Winter Ski Weekend — heating + diesel CHP
A3: A. Heat demand
A4: ΔT (indoor − outdoor) | C4: =Assumptions!$B$12-Assumptions!$B$13 -> 30 | D4: K
A5: Cabin heating load | C5: =Assumptions!$B$10*C4*24/1000 -> 29.232 | D5: kWh thermal
A6: DHW thermal demand | C6: =Assumptions!$B$5*Assumptions!$B$22*Assumptions!$B$26*(Assumptions!$B$23-Assumptions!$B$24)/1000 -> 3.7216 | D6: kWh thermal
A7: Total heat demand | C7: =C5+C6 -> 32.9536 | D7: kWh thermal
A8: B. Pack-only option (no genset)
A9: Base electric demand | C9: ='Electrical Loads'!$D$21 -> 10.735 | D9: kWh
A10: Heat-pump electricity for all heat | C10: =C7/Assumptions!$B$20 -> 14.978909 | D10: kWh
A11: Solar generation (winter, parked) | C11: =Assumptions!$B$34*Assumptions!$B$36*Assumptions!$B$37 -> 10.824 | D11: kWh
A12: Net pack draw / day (pack-only) | C12: =C9+C10-C11 -> 14.889909 | D12: kWh/day
A13: C. Diesel CHP option (hold pack at net-zero)
A14: Heat recovered per genset-hour | C14: =Assumptions!$B$28/Assumptions!$B$29*Assumptions!$B$30 -> 6.4166667 | D14: kWh/h
A15: Genset runtime to net-zero pack | C15: =(C9+C7/Assumptions!$B$20-C11)/(Assumptions!$B$28+C14/Assumptions!$B$20) -> 2.3205053 | D15: h/day
A16: CHP heat delivered | C16: =C14*C15 -> 14.889909 | D16: kWh thermal
A17: Diesel use | C17: =Assumptions!$B$28*C15/Assumptions!$B$29/Assumptions!$B$31 -> 2.7072562 | D17: L/day

Sheet Pack & Range
A1: Shared Pack — autonomy & range
A3: A. Energy split
A4: Usable pack energy | C4: =Assumptions!$B$39*Assumptions!$B$40 -> 270 | D4: kWh
A5: House-available (after drive reserve) | C5: =C4-Assumptions!$B$41 -> 190 | D5: kWh
A6: Summer daily house demand | C6: ='Summer Day'!C13 -> 15.2582 | D6: kWh
A7: Winter daily draw (pack-only) | C7: ='Winter Weekend'!C12 -> 14.889909 | D7: kWh
A8: House autonomy — summer | C8: =IF('Summer Day'!C13>0,C5/'Summer Day'!C13,0) -> 12.452321 | D8: days
A9: House autonomy — winter (pack-only) | C9: =IF('Winter Weekend'!C12>0,C5/'Winter Weekend'!C12,999) -> 12.76032 | D9: days
A10: C. With winter solar + genset
A11: Genset runtime to hold pack | C11: ='Winter Weekend'!C15 -> 2.3205053 | D11: h/day
A12: Diesel per day (held indefinitely) | C12: ='Winter Weekend'!C17 -> 2.7072562 | D12: L/day
A13: D. Driving range
A14: Range on usable pack | C14: =C4/Assumptions!$B$42 -> 245.45455 | D14: miles
A15: Range above drive reserve | C15: =Assumptions!$B$41/Assumptions!$B$42 -> 72.727273 | D15: miles
